[2023-08-22 23:36:55,891] {taskinstance.py:1179} INFO - Dependencies all met for <TaskInstance: Nasdaq.transformar_data scheduled__2023-08-21T00:00:00+00:00 [queued]>
[2023-08-22 23:36:55,904] {taskinstance.py:1179} INFO - Dependencies all met for <TaskInstance: Nasdaq.transformar_data scheduled__2023-08-21T00:00:00+00:00 [queued]>
[2023-08-22 23:36:55,905] {taskinstance.py:1376} INFO - 
--------------------------------------------------------------------------------
[2023-08-22 23:36:55,905] {taskinstance.py:1377} INFO - Starting attempt 2 of 6
[2023-08-22 23:36:55,906] {taskinstance.py:1378} INFO - 
--------------------------------------------------------------------------------
[2023-08-22 23:36:55,922] {taskinstance.py:1397} INFO - Executing <Task(PythonOperator): transformar_data> on 2023-08-21 00:00:00+00:00
[2023-08-22 23:36:55,927] {standard_task_runner.py:52} INFO - Started process 385 to run task
[2023-08-22 23:36:55,931] {standard_task_runner.py:79} INFO - Running: ['***', 'tasks', 'run', 'Nasdaq', 'transformar_data', 'scheduled__2023-08-21T00:00:00+00:00', '--job-id', '5', '--raw', '--subdir', 'DAGS_FOLDER/Api_Nasdaq.py', '--cfg-path', '/tmp/tmpz823oppf', '--error-file', '/tmp/tmpyhuy_tfa']
[2023-08-22 23:36:55,932] {standard_task_runner.py:80} INFO - Job 5: Subtask transformar_data
[2023-08-22 23:36:56,019] {task_command.py:371} INFO - Running <TaskInstance: Nasdaq.transformar_data scheduled__2023-08-21T00:00:00+00:00 [running]> on host dec66e93643e
[2023-08-22 23:36:56,063] {taskinstance.py:1909} ERROR - Task failed with exception
Traceback (most recent call last):
  File "/home/airflow/.local/lib/python3.7/site-packages/airflow/models/taskinstance.py", line 1471, in _run_raw_task
    self._execute_task_with_callbacks(context, test_mode)
  File "/home/airflow/.local/lib/python3.7/site-packages/airflow/models/taskinstance.py", line 1575, in _execute_task_with_callbacks
    task_orig = self.render_templates(context=context)
  File "/home/airflow/.local/lib/python3.7/site-packages/airflow/models/taskinstance.py", line 2232, in render_templates
    rendered_task = self.task.render_template_fields(context)
  File "/home/airflow/.local/lib/python3.7/site-packages/airflow/models/baseoperator.py", line 1188, in render_template_fields
    self._do_render_template_fields(self, self.template_fields, context, jinja_env, set())
  File "/home/airflow/.local/lib/python3.7/site-packages/airflow/utils/session.py", line 71, in wrapper
    return func(*args, session=session, **kwargs)
  File "/home/airflow/.local/lib/python3.7/site-packages/airflow/models/abstractoperator.py", line 347, in _do_render_template_fields
    seen_oids,
  File "/home/airflow/.local/lib/python3.7/site-packages/airflow/models/abstractoperator.py", line 401, in render_template
    return [self.render_template(element, context, jinja_env) for element in value]
  File "/home/airflow/.local/lib/python3.7/site-packages/airflow/models/abstractoperator.py", line 401, in <listcomp>
    return [self.render_template(element, context, jinja_env) for element in value]
  File "/home/airflow/.local/lib/python3.7/site-packages/airflow/models/abstractoperator.py", line 390, in render_template
    return render_template_to_string(template, context)
  File "/home/airflow/.local/lib/python3.7/site-packages/airflow/utils/helpers.py", line 296, in render_template_to_string
    return render_template(template, context, native=False)
  File "/home/airflow/.local/lib/python3.7/site-packages/airflow/utils/helpers.py", line 291, in render_template
    return "".join(nodes)
  File "<template>", line 12, in root
  File "/home/airflow/.local/lib/python3.7/site-packages/jinja2/runtime.py", line 852, in _fail_with_undefined_error
    raise self._undefined_exception(self._undefined_message)
jinja2.exceptions.UndefinedError: 'datos_file' is undefined
[2023-08-22 23:36:56,080] {taskinstance.py:1420} INFO - Marking task as UP_FOR_RETRY. dag_id=Nasdaq, task_id=transformar_data, execution_date=20230821T000000, start_date=20230822T233655, end_date=20230822T233656
[2023-08-22 23:36:56,091] {standard_task_runner.py:97} ERROR - Failed to execute job 5 for task transformar_data ('datos_file' is undefined; 385)
[2023-08-22 23:36:56,103] {local_task_job.py:156} INFO - Task exited with return code 1
[2023-08-22 23:36:56,152] {local_task_job.py:273} INFO - 0 downstream tasks scheduled from follow-on schedule check
